<sdf version='1.9'> /*the usvcopy one with altered rotation in the world
  <model name='oystermaran'>
    <link name='base_link'>
      <inertial>
        <pose>0 0 0 0 0 0</pose>
        <mass>2.5</mass>
        <inertia>
          <ixx>0.025999999999999999</ixx>
          <ixy>0</ixy>
          <ixz>0</ixz>
          <iyy>0.053999999999999999</iyy>
          <iyz>0</iyz>
          <izz>0.078</izz>
        </inertia>
      </inertial>
      <collision name='base_link_fixed_joint_lump__left_pontoon_col_collision'>
        <pose>0 0.18 -0.06 0 0 0</pose>
        <geometry>
          <box>
            <size>0.55 0.13 0.13</size>
          </box>
        </geometry>
      </collision>
      <collision name='base_link_fixed_joint_lump__right_pontoon_col_collision_1'>
        <pose>0 -0.18 -0.06 0 0 0</pose>
        <geometry>
          <box>
            <size>0.55 0.13 0.13</size>
          </box>
        </geometry>
      </collision>
      <visual name='base_link_fixed_joint_lump__hull_visual_visual'>
        <pose>0 0 0 0 0 0</pose>
        <geometry>
          <mesh>
            <scale>0.001 0.001 0.001</scale>
            <uri>file:///home/solvnik/usv_ws/src/usv_description/meshes/base_link.stl</uri>
          </mesh>
        </geometry>
      </visual>
    </link>
    <joint name='left_fan_joint' type='revolute'>
      <pose relative_to='base_link'>0.5483 0.1947 -0.0458 0 0 0</pose>
      <parent>base_link</parent>
      <child>left_fan</child>
      <axis>
        <xyz>0 0 1</xyz>
        <limit>
          <lower>-10000000000000000</lower>
          <upper>10000000000000000</upper>
        </limit>
        <dynamics>
          <spring_reference>0</spring_reference>
          <spring_stiffness>0</spring_stiffness>
        </dynamics>
      </axis>
    </joint>
    <link name='left_fan'>
      <pose relative_to='left_fan_joint'>0 0 0 0 0 0</pose>
      <inertial>
        <pose>0 0 0 0 0 0</pose>
        <mass>0.050000000000000003</mass>
        <inertia>
          <ixx>0.0001</ixx>
          <ixy>0</ixy>
          <ixz>0</ixz>
          <iyy>0.0001</iyy>
          <iyz>0</iyz>
          <izz>0.0001</izz>
        </inertia>
      </inertial>
      <collision name='left_fan_collision'>
        <pose>0 0 0 0 0 0</pose>
        <geometry>
          <cylinder>
            <length>0.01</length>
            <radius>0.029999999999999999</radius>
          </cylinder>
        </geometry>
      </collision>
      <visual name='left_fan_visual'>
        <pose>-0.5483 -0.1947 0.0458 0 0 0</pose>
        <geometry>
          <mesh>
            <scale>0.001 0.001 0.001</scale>
            <uri>file:///home/solvnik/usv_ws/src/usv_description/meshes/left_fan.stl</uri>
          </mesh>
        </geometry>
      </visual>
    </link>
    <joint name='right_fan_joint' type='revolute'>
      <pose relative_to='base_link'>-0.0017 0.1947 -0.0458 0 0 0</pose>
      <parent>base_link</parent>
      <child>right_fan</child>
      <axis>
        <xyz>0 0 1</xyz>
        <limit>
          <lower>-10000000000000000</lower>
          <upper>10000000000000000</upper>
        </limit>
        <dynamics>
          <spring_reference>0</spring_reference>
          <spring_stiffness>0</spring_stiffness>
        </dynamics>
      </axis>
    </joint>
    <link name='right_fan'>
      <pose relative_to='right_fan_joint'>0 0 0 0 0 0</pose>
      <inertial>
        <pose>0 0 0 0 0 0</pose>
        <mass>0.050000000000000003</mass>
        <inertia>
          <ixx>0.0001</ixx>
          <ixy>0</ixy>
          <ixz>0</ixz>
          <iyy>0.0001</iyy>
          <iyz>0</iyz>
          <izz>0.0001</izz>
        </inertia>
      </inertial>
    </link>
  </model>
</sdf>
/* the suggested correction- */




<sdf version='1.9'>
  <model name='oystermaran'>
    <link name='base_link'>
      <inertial>
        <pose>0 0 0 0 0 0</pose>
        <mass>2.5</mass>
        <inertia>
          <ixx>0.026</ixx>
          <ixy>0</ixy>
          <ixz>0</ixz>
          <iyy>0.054</iyy>
          <iyz>0</iyz>
          <izz>0.078</izz>
        </inertia>
      </inertial>

      <collision name='base_link_fixed_joint_lump__left_pontoon_col_collision'>
        <pose>0 0.18 -0.06 0 0 0</pose>
        <geometry>
          <box>
            <size>0.55 0.13 0.13</size>
          </box>
        </geometry>
      </collision>

      <collision name='base_link_fixed_joint_lump__right_pontoon_col_collision_1'>
        <pose>0 -0.18 -0.06 0 0 0</pose>
        <geometry>
          <box>
            <size>0.55 0.13 0.13</size>
          </box>
        </geometry>
      </collision>

      <visual name='base_link_fixed_joint_lump__hull_visual_visual'>
        <pose>0 0 0 0 0 0</pose>
        <geometry>
          <mesh>
            <scale>0.001 0.001 0.001</scale>
            <uri>file:///home/solvnik/usv_ws/src/usv_description/meshes/base_link.stl</uri>
          </mesh>
        </geometry>
        <material>
          <ambient>0.1 0.3 0.8 1</ambient>
          <diffuse>0.1 0.3 0.8 1</diffuse>
          <specular>0.5 0.5 0.5 1</specular>
        </material>
      </visual>
    </link>

    <joint name='left_fan_joint' type='revolute'>
      <pose relative_to='base_link'>0.5483 0.1947 -0.0458 0 0 0</pose>
      <parent>base_link</parent>
      <child>left_fan</child>
      <axis>
        <xyz>1 0 0</xyz>
        <limit>
          <lower>-1e16</lower>
          <upper>1e16</upper>
        </limit>
        <dynamics>
          <spring_reference>0</spring_reference>
          <spring_stiffness>0</spring_stiffness>
        </dynamics>
      </axis>
    </joint>

    <link name='left_fan'>
      <pose relative_to='left_fan_joint'>0 0 0 0 0 0</pose>
      <inertial>
        <pose>0 0 0 0 0 0</pose>
        <mass>0.05</mass>
        <inertia>
          <ixx>0.0001</ixx><ixy>0</ixy><ixz>0</ixz>
          <iyy>0.0001</iyy><iyz>0</iyz><izz>0.0001</izz>
        </inertia>
      </inertial>
      
      <collision name='left_fan_collision'>
        <pose>-0.5483 -0.1947 0.0458 0 0 0</pose>
        <geometry>
          <cylinder>
            <length>0.01</length>
            <radius>0.03</radius>
          </cylinder>
        </geometry>
      </collision>

      <visual name='left_fan_visual'>
        <pose>-0.5483 -0.1947 0.0458 0 0 0</pose>
        <geometry>
          <mesh>
            <scale>0.001 0.001 0.001</scale>
            <uri>file:///home/solvnik/usv_ws/src/usv_description/meshes/left_fan.stl</uri>
          </mesh>
        </geometry>
        <material>
          <ambient>0.2 0.2 0.2 1</ambient>
          <diffuse>0.2 0.2 0.2 1</diffuse>
        </material>
      </visual>
    </link>

    <joint name='right_fan_joint' type='revolute'>
      <pose relative_to='base_link'>0.5483 -0.1947 -0.0458 0 0 0</pose>
      <parent>base_link</parent>
      <child>right_fan</child>
      <axis>
        <xyz>1 0 0</xyz>
        <limit>
          <lower>-1e16</lower>
          <upper>1e16</upper>
        </limit>
        <dynamics>
          <spring_reference>0</spring_reference>
          <spring_stiffness>0</spring_stiffness>
        </dynamics>
      </axis>
    </joint>

    <link name='right_fan'>
      <pose relative_to='right_fan_joint'>0 0 0 0 0 0</pose>
      <inertial>
        <pose>0 0 0 0 0 0</pose>
        <mass>0.05</mass>
        <inertia>
          <ixx>0.0001</ixx><ixy>0</ixy><ixz>0</ixz>
          <iyy>0.0001</iyy><iyz>0</iyz><izz>0.0001</izz>
        </inertia>
      </inertial>

      <collision name='right_fan_collision'>
        <pose>-0.5483 0.1947 0.0458 0 0 0</pose>
        <geometry>
          <cylinder>
            <length>0.01</length>
            <radius>0.03</radius>
          </cylinder>
        </geometry>
      </collision>

      <visual name='right_fan_visual'>
        <pose>-0.5483 0.1947 0.0458 0 0 0</pose>
        <geometry>
          <mesh>
            <scale>0.001 0.001 0.001</scale>
            <uri>file:///home/solvnik/usv_ws/src/usv_description/meshes/right_fan.stl</uri>
          </mesh>
        </geometry>
        <material>
          <ambient>0.2 0.2 0.2 1</ambient>
          <diffuse>0.2 0.2 0.2 1</diffuse>
        </material>
      </visual>
    </link>
  </model>
</sdf>
